<robot
  name="ship_shaft">
  <link
    name="shaft_base">
    <inertial>
      <origin
        xyz="-0.0482124024715684 -2.11997733364886E-08 0.0437837615145441"
        rpy="0 0 0" />
      <mass
        value="107.388668742931" />
      <inertia
        ixx="1.22100761859766"
        ixy="2.35408130593514E-08"
        ixz="-0.213069196033121"
        iyy="6.93483368955367"
        iyz="9.15237828430063E-08"
        izz="7.80996151767761" />
    </inertial>
    <visual>
      <origin
        xyz="0 0 0"
        rpy="0 0 0" />
      <geometry>
        <mesh
          filename="package://inspection_sim/meshes/base_link.STL" />
      </geometry>
      <material
        name="">
        <color
          rgba="0.898039215686275 0.917647058823529 0.929411764705882 1" />
      </material>
    </visual>
    <collision>
      <origin
        xyz="0 0 0"
        rpy="0 0 0" />
      <geometry>
        <mesh
          filename="package://inspection_sim/meshes/base_link.STL" />
      </geometry>
    </collision>
  </link>
  <link
    name="Empty_Link">
    <inertial>
      <origin
        xyz="-1.58611210162585E-05 -2.07330212466383E-05 0.308504147181496"
        rpy="0 0 0" />
      <mass
        value="1.48084133626181" />
      <inertia
        ixx="0.0481596319576275"
        ixy="-1.10330933849115E-07"
        ixz="-6.10810168884322E-08"
        iyy="0.0481594925561947"
        iyz="4.06445617475966E-08"
        izz="0.000266229514042342" />
    </inertial>
    <visual>
      <origin
        xyz="0 0 0"
        rpy="0 0 0" />
      <geometry>
        <mesh
          filename="package://inspection_sim/meshes/Empty_Link.STL" />
      </geometry>
      <material
        name="">
        <color
          rgba="0.647058823529412 0.619607843137255 0.588235294117647 1" />
      </material>
    </visual>
    <collision>
      <origin
        xyz="0 0 0"
        rpy="0 0 0" />
      <geometry>
        <mesh
          filename="package://inspection_sim/meshes/Empty_Link.STL" />
      </geometry>
    </collision>
  </link>
  <joint
    name="joint1"
    type="continuous">
    <origin
      xyz="0 -0.175 0"
      rpy="1.5707963267949 0.603482602756735 -1.5707963267949" />
    <parent
      link="shaft_base" />
    <child
      link="Empty_Link" />
    <axis
      xyz="0 0 1" />
  </joint>
</robot>
